<?xml version="1.0" encoding="UTF-8"?>
<testng-results skipped="0" failed="1" ignored="0" total="1" passed="0">
  <reporter-output>
  </reporter-output>
  <suite name="InetBankingV1" duration-ms="19165" started-at="2021-01-27T14:32:50Z" finished-at="2021-01-27T14:33:09Z">
    <groups>
    </groups>
    <test name="BankingApp test" duration-ms="19165" started-at="2021-01-27T14:32:50Z" finished-at="2021-01-27T14:33:09Z">
      <class name="com.inetBanking.testCases.TC_LoginTest_001">
        <test-method status="PASS" signature="setUp(java.lang.String)[pri:0, instance:com.inetBanking.testCases.TC_LoginTest_001@4667ae56]" name="setUp" is-config="true" duration-ms="12806" started-at="2021-01-27T14:32:50Z" finished-at="2021-01-27T14:33:03Z">
          <params>
            <param index="0">
              <value>
                <![CDATA[chrome]]>
              </value>
            </param>
          </params>
          <reporter-output>
          </reporter-output>
        </test-method> <!-- setUp -->
        <test-method status="FAIL" signature="loginTest()[pri:0, instance:com.inetBanking.testCases.TC_LoginTest_001@4667ae56]" name="loginTest" duration-ms="5433" started-at="2021-01-27T14:33:03Z" finished-at="2021-01-27T14:33:08Z">
          <exception class="java.lang.AssertionError">
            <message>
              <![CDATA[expected [true] but found [false]]]>
            </message>
            <full-stacktrace>
              <![CDATA[java.lang.AssertionError: expected [true] but found [false]
at org.testng.Assert.fail(Assert.java:96)
at org.testng.Assert.failNotEquals(Assert.java:776)
at org.testng.Assert.assertTrue(Assert.java:44)
at org.testng.Assert.assertTrue(Assert.java:54)
at com.inetBanking.testCases.TC_LoginTest_001.loginTest(TC_LoginTest_001.java:34)
at sun.reflect.NativeMethodAccessorImpl.invoke0(Native Method)
at sun.reflect.NativeMethodAccessorImpl.invoke(Unknown Source)
at sun.reflect.DelegatingMethodAccessorImpl.invoke(Unknown Source)
at java.lang.reflect.Method.invoke(Unknown Source)
at org.testng.internal.MethodInvocationHelper.invokeMethod(MethodInvocationHelper.java:124)
at org.testng.internal.Invoker.invokeMethod(Invoker.java:583)
at org.testng.internal.Invoker.invokeTestMethod(Invoker.java:719)
at org.testng.internal.Invoker.invokeTestMethods(Invoker.java:989)
at org.testng.internal.TestMethodWorker.invokeTestMethods(TestMethodWorker.java:125)
at org.testng.internal.TestMethodWorker.run(TestMethodWorker.java:109)
at org.testng.TestRunner.privateRun(TestRunner.java:648)
at org.testng.TestRunner.run(TestRunner.java:505)
at org.testng.SuiteRunner.runTest(SuiteRunner.java:455)
at org.testng.SuiteRunner.runSequentially(SuiteRunner.java:450)
at org.testng.SuiteRunner.privateRun(SuiteRunner.java:415)
at org.testng.SuiteRunner.run(SuiteRunner.java:364)
at org.testng.SuiteRunnerWorker.runSuite(SuiteRunnerWorker.java:52)
at org.testng.SuiteRunnerWorker.run(SuiteRunnerWorker.java:84)
at org.testng.TestNG.runSuitesSequentially(TestNG.java:1208)
at org.testng.TestNG.runSuitesLocally(TestNG.java:1137)
at org.testng.TestNG.runSuites(TestNG.java:1049)
at org.testng.TestNG.run(TestNG.java:1017)
at org.testng.remote.AbstractRemoteTestNG.run(AbstractRemoteTestNG.java:132)
at org.testng.remote.RemoteTestNG.initAndRun(RemoteTestNG.java:236)
at org.testng.remote.RemoteTestNG.main(RemoteTestNG.java:81)
]]>
            </full-stacktrace>
          </exception> <!-- java.lang.AssertionError -->
          <reporter-output>
          </reporter-output>
        </test-method> <!-- loginTest -->
        <test-method status="PASS" signature="tearDown()[pri:0, instance:com.inetBanking.testCases.TC_LoginTest_001@4667ae56]" name="tearDown" is-config="true" duration-ms="861" started-at="2021-01-27T14:33:08Z" finished-at="2021-01-27T14:33:09Z">
          <reporter-output>
          </reporter-output>
        </test-method> <!-- tearDown -->
      </class> <!-- com.inetBanking.testCases.TC_LoginTest_001 -->
    </test> <!-- BankingApp test -->
  </suite> <!-- InetBankingV1 -->
</testng-results>
